Traceback (most recent call last):
  File "/home/celien/miniconda3/envs/ml_venv/lib/python3.9/site-packages/nbclient/client.py", line 782, in _async_poll_for_reply
    msg = await ensure_async(self.kc.shell_channel.get_msg(timeout=new_timeout))
  File "/home/celien/miniconda3/envs/ml_venv/lib/python3.9/site-packages/jupyter_core/utils/__init__.py", line 198, in ensure_async
    result = await obj
  File "/home/celien/miniconda3/envs/ml_venv/lib/python3.9/site-packages/jupyter_client/channels.py", line 315, in get_msg
    raise Empty
_queue.Empty

During handling of the above exception, another exception occurred:

Traceback (most recent call last):
  File "/home/celien/miniconda3/envs/ml_venv/lib/python3.9/site-packages/jupyter_cache/executors/utils.py", line 58, in single_nb_execution
    executenb(
  File "/home/celien/miniconda3/envs/ml_venv/lib/python3.9/site-packages/nbclient/client.py", line 1314, in execute
    return NotebookClient(nb=nb, resources=resources, km=km, **kwargs).execute()
  File "/home/celien/miniconda3/envs/ml_venv/lib/python3.9/site-packages/jupyter_core/utils/__init__.py", line 165, in wrapped
    return loop.run_until_complete(inner)
  File "/home/celien/miniconda3/envs/ml_venv/lib/python3.9/asyncio/base_events.py", line 647, in run_until_complete
    return future.result()
  File "/home/celien/miniconda3/envs/ml_venv/lib/python3.9/site-packages/nbclient/client.py", line 709, in async_execute
    await self.async_execute_cell(
  File "/home/celien/miniconda3/envs/ml_venv/lib/python3.9/site-packages/nbclient/client.py", line 1005, in async_execute_cell
    exec_reply = await self.task_poll_for_reply
  File "/home/celien/miniconda3/envs/ml_venv/lib/python3.9/site-packages/nbclient/client.py", line 806, in _async_poll_for_reply
    error_on_timeout_execute_reply = await self._async_handle_timeout(timeout, cell)
  File "/home/celien/miniconda3/envs/ml_venv/lib/python3.9/site-packages/nbclient/client.py", line 856, in _async_handle_timeout
    raise CellTimeoutError.error_from_timeout_and_cell(
nbclient.exceptions.CellTimeoutError: A cell timed out while it was being executed, after 30 seconds.
The message was: Cell execution timed out.
Here is a preview of the cell contents:
-------------------
['from sklearn.model_selection import GridSearchCV', 'from utils import grid_search_by_hand, model_evaluation_clf', 'from copy import deepcopy', '', 'import warnings']
...
["    results_hand.loc[2*i] = [model_name, eval_hand['accuracy'], eval_hand['precision'], eval_hand['recall'], eval_hand['f1'], eval_hand['roc_auc']]", "    results_hand.loc[2*i+1] = [model_name + ' (sc)', eval_hand_sc['accuracy'], eval_hand_sc['precision'], eval_hand_sc['recall'], eval_hand_sc['f1'], eval_hand_sc['roc_auc']]", '', "results_gs = results_gs.sort_values(by='Recall', ascending=False)", "results_hand = results_hand.sort_values(by='Recall', ascending=False)"]
-------------------

