Traceback (most recent call last):
  File "/Users/leonardovaia/miniconda3/envs/ml_venv/lib/python3.9/site-packages/jupyter_cache/executors/utils.py", line 58, in single_nb_execution
    executenb(
  File "/Users/leonardovaia/miniconda3/envs/ml_venv/lib/python3.9/site-packages/nbclient/client.py", line 1314, in execute
    return NotebookClient(nb=nb, resources=resources, km=km, **kwargs).execute()
  File "/Users/leonardovaia/miniconda3/envs/ml_venv/lib/python3.9/site-packages/jupyter_core/utils/__init__.py", line 173, in wrapped
    return loop.run_until_complete(inner)
  File "/Users/leonardovaia/miniconda3/envs/ml_venv/lib/python3.9/asyncio/base_events.py", line 647, in run_until_complete
    return future.result()
  File "/Users/leonardovaia/miniconda3/envs/ml_venv/lib/python3.9/site-packages/nbclient/client.py", line 709, in async_execute
    await self.async_execute_cell(
  File "/Users/leonardovaia/miniconda3/envs/ml_venv/lib/python3.9/site-packages/nbclient/client.py", line 1062, in async_execute_cell
    await self._check_raise_for_error(cell, cell_index, exec_reply)
  File "/Users/leonardovaia/miniconda3/envs/ml_venv/lib/python3.9/site-packages/nbclient/client.py", line 918, in _check_raise_for_error
    raise CellExecutionError.from_cell_and_msg(cell, exec_reply_content)
nbclient.exceptions.CellExecutionError: An error occurred while executing the following cell:
------------------
import plotly.graph_objects as go

for col in data_eda.columns:
    fig = go.Figure()

    fig.add_trace(go.Scatter(x=data_wind['Fecha'], y=data_wind[col], mode='lines', name=col))

    fig.update_layout(title=f'{col} over time',
                  xaxis_title='Date', 
                  yaxis_title=col,
                  margin=dict(l=20, r=20, t=40, b=20))
    fig.show()

------------------


[0;31m---------------------------------------------------------------------------[0m
[0;31mModuleNotFoundError[0m                       Traceback (most recent call last)
Cell [0;32mIn[18], line 1[0m
[0;32m----> 1[0m [38;5;28;01mimport[39;00m [38;5;21;01mplotly[39;00m[38;5;21;01m.[39;00m[38;5;21;01mgraph_objects[39;00m [38;5;28;01mas[39;00m [38;5;21;01mgo[39;00m
[1;32m      3[0m [38;5;28;01mfor[39;00m col [38;5;129;01min[39;00m data_eda[38;5;241m.[39mcolumns:
[1;32m      4[0m     fig [38;5;241m=[39m go[38;5;241m.[39mFigure()

[0;31mModuleNotFoundError[0m: No module named 'plotly'

