Traceback (most recent call last):
  File "/home/celien/miniconda3/envs/ml_venv/lib/python3.9/site-packages/nbclient/client.py", line 782, in _async_poll_for_reply
    msg = await ensure_async(self.kc.shell_channel.get_msg(timeout=new_timeout))
  File "/home/celien/miniconda3/envs/ml_venv/lib/python3.9/site-packages/jupyter_core/utils/__init__.py", line 198, in ensure_async
    result = await obj
  File "/home/celien/miniconda3/envs/ml_venv/lib/python3.9/site-packages/jupyter_client/channels.py", line 315, in get_msg
    raise Empty
_queue.Empty

During handling of the above exception, another exception occurred:

Traceback (most recent call last):
  File "/home/celien/miniconda3/envs/ml_venv/lib/python3.9/site-packages/jupyter_cache/executors/utils.py", line 58, in single_nb_execution
    executenb(
  File "/home/celien/miniconda3/envs/ml_venv/lib/python3.9/site-packages/nbclient/client.py", line 1314, in execute
    return NotebookClient(nb=nb, resources=resources, km=km, **kwargs).execute()
  File "/home/celien/miniconda3/envs/ml_venv/lib/python3.9/site-packages/jupyter_core/utils/__init__.py", line 165, in wrapped
    return loop.run_until_complete(inner)
  File "/home/celien/miniconda3/envs/ml_venv/lib/python3.9/asyncio/base_events.py", line 647, in run_until_complete
    return future.result()
  File "/home/celien/miniconda3/envs/ml_venv/lib/python3.9/site-packages/nbclient/client.py", line 709, in async_execute
    await self.async_execute_cell(
  File "/home/celien/miniconda3/envs/ml_venv/lib/python3.9/site-packages/nbclient/client.py", line 1005, in async_execute_cell
    exec_reply = await self.task_poll_for_reply
  File "/home/celien/miniconda3/envs/ml_venv/lib/python3.9/site-packages/nbclient/client.py", line 806, in _async_poll_for_reply
    error_on_timeout_execute_reply = await self._async_handle_timeout(timeout, cell)
  File "/home/celien/miniconda3/envs/ml_venv/lib/python3.9/site-packages/nbclient/client.py", line 856, in _async_handle_timeout
    raise CellTimeoutError.error_from_timeout_and_cell(
nbclient.exceptions.CellTimeoutError: A cell timed out while it was being executed, after 30 seconds.
The message was: Cell execution timed out.
Here is a preview of the cell contents:
-------------------
['from utils import model_evaluation_clf', 'from time import time', 'from copy import deepcopy', '', 'import warnings']
...
['', "    results.loc[2*i] = [model_name, eval['accuracy'], eval['precision'], eval['recall'], eval['f1'], eval['roc_auc'], round(end_time - start_time, 1)]", "    results.loc[2*i+1] = [model_name + ' (res)', eval_res['accuracy'], eval_res['precision'], eval_res['recall'], eval_res['f1'], eval_res['roc_auc'], round(end_time_res - start_time_res, 1)]", '', '    print(f"{round(sum([end_time - start_time, end_time_res - start_time_res]), 1)}s")']
-------------------

